<?xml version="1.0" encoding="UTF-8"?>
<!-- Generated by org.testng.reporters.JUnitXMLReporter -->
<testsuite ignored="0" hostname="K_Anderson" failures="2" tests="14" name="edgeTest" time="163.72" errors="0" timestamp="2025-05-20T17:47:27 EDT">
  <testcase classname="testCases.TC01_LaunchApplication" name="testLaunchApplication" time="1.378"/>
  <testcase classname="testCases.TC03_AddToCart" name="testAddToCart" time="6.233"/>
  <testcase classname="testCases.TC05_AddToWishList" name="testAddToWishList" time="14.51">
    <skipped/>
  </testcase> <!-- testAddToWishList -->
  <testcase classname="testCases.TC05_AddToWishList" name="testAddToWishList" time="10.312">
    <skipped/>
  </testcase> <!-- testAddToWishList -->
  <testcase classname="testCases.TC05_AddToWishList" name="testAddToWishList" time="10.148">
    <failure type="java.lang.AssertionError" message="Test failed due to unexpected exception.">
      <![CDATA[java.lang.AssertionError: Test failed due to unexpected exception.
at testCases.TC05_AddToWishList.testAddToWishList(TC05_AddToWishList.java:68)
at java.base/java.util.ArrayList.forEach(ArrayList.java:1596)
at java.base/java.util.concurrent.FutureTask.run(FutureTask.java:317)
at java.base/java.util.concurrent.ThreadPoolExecutor.runWorker(ThreadPoolExecutor.java:1144)
at java.base/java.util.concurrent.ThreadPoolExecutor$Worker.run(ThreadPoolExecutor.java:642)
at java.base/java.lang.Thread.run(Thread.java:1583)
... Removed 16 stack frames]]>
    </failure>
  </testcase> <!-- testAddToWishList -->
  <testcase classname="testCases.TC06_AddAffiliate" name="testAddAffiliate" time="5.713"/>
  <testcase classname="testCases.TC02_Login" name="testLogin" time="3.579"/>
  <testcase classname="testCases.TC02_Login" name="testLogin" time="3.047"/>
  <testcase classname="testCases.TC02_Login" name="testLogin" time="3.176"/>
  <testcase classname="testCases.TC02_Login" name="testLogin" time="2.847"/>
  <testcase classname="testCases.TC02_Login" name="testLogin" time="3.117"/>
  <testcase classname="testCases.TC04_CompletePurchase" name="testCompletePurchase" time="21.363">
    <skipped/>
  </testcase> <!-- testCompletePurchase -->
  <testcase classname="testCases.TC04_CompletePurchase" name="testCompletePurchase" time="15.938">
    <skipped/>
  </testcase> <!-- testCompletePurchase -->
  <testcase classname="testCases.TC04_CompletePurchase" name="testCompletePurchase" time="15.851">
    <failure type="java.lang.AssertionError" message="Test failed due to unexpected exception.">
      <![CDATA[java.lang.AssertionError: Test failed due to unexpected exception.
at testCases.TC04_CompletePurchase.testCompletePurchase(TC04_CompletePurchase.java:81)
at java.base/java.util.ArrayList.forEach(ArrayList.java:1596)
at java.base/java.util.concurrent.FutureTask.run(FutureTask.java:317)
at java.base/java.util.concurrent.ThreadPoolExecutor.runWorker(ThreadPoolExecutor.java:1144)
at java.base/java.util.concurrent.ThreadPoolExecutor$Worker.run(ThreadPoolExecutor.java:642)
at java.base/java.lang.Thread.run(Thread.java:1583)
... Removed 16 stack frames]]>
    </failure>
  </testcase> <!-- testCompletePurchase -->
</testsuite> <!-- edgeTest -->
